<?xml version="1.0" encoding="UTF-8"?>
<testng-results skipped="0" failed="2" total="5" passed="3">
  <reporter-output>
  </reporter-output>
  <suite name="Suite" duration-ms="295275" started-at="2016-10-18T07:02:15Z" finished-at="2016-10-18T07:07:11Z">
    <groups>
    </groups>
    <test name="Test" duration-ms="295275" started-at="2016-10-18T07:02:15Z" finished-at="2016-10-18T07:07:11Z">
      <class name="com.my.test.TestCase">
        <test-method status="PASS" signature="Regist()[pri:0, instance:com.my.test.TestCase@7c6908d7]" name="Regist" duration-ms="33579" started-at="2016-10-18T15:02:15Z" finished-at="2016-10-18T15:02:49Z">
          <reporter-output>
          </reporter-output>
        </test-method> <!-- Regist -->
        <test-method status="PASS" signature="Bank()[pri:0, instance:com.my.test.TestCase@7c6908d7]" name="Bank" duration-ms="108882" started-at="2016-10-18T15:02:49Z" finished-at="2016-10-18T15:04:38Z">
          <reporter-output>
          </reporter-output>
        </test-method> <!-- Bank -->
        <test-method status="FAIL" signature="Recharge()[pri:0, instance:com.my.test.TestCase@7c6908d7]" name="Recharge" duration-ms="55086" started-at="2016-10-18T15:04:38Z" finished-at="2016-10-18T15:05:33Z">
          <exception class="java.lang.IndexOutOfBoundsException">
            <message>
              <![CDATA[Index: 2, Size: 1]]>
            </message>
            <full-stacktrace>
              <![CDATA[java.lang.IndexOutOfBoundsException: Index: 2, Size: 1
	at java.util.ArrayList.rangeCheck(ArrayList.java:653)
	at java.util.ArrayList.get(ArrayList.java:429)
	at com.my.business.SimpleBusiness.Recharge(Unknown Source)
	at com.my.test.TestCase.Recharge(Unknown Source)
	at sun.reflect.NativeMethodAccessorImpl.invoke0(Native Method)
	at sun.reflect.NativeMethodAccessorImpl.invoke(NativeMethodAccessorImpl.java:62)
	at sun.reflect.DelegatingMethodAccessorImpl.invoke(DelegatingMethodAccessorImpl.java:43)
	at java.lang.reflect.Method.invoke(Method.java:498)
	at org.testng.internal.MethodInvocationHelper.invokeMethod(MethodInvocationHelper.java:85)
	at org.testng.internal.Invoker.invokeMethod(Invoker.java:639)
	at org.testng.internal.Invoker.invokeTestMethod(Invoker.java:816)
	at org.testng.internal.Invoker.invokeTestMethods(Invoker.java:1124)
	at org.testng.internal.TestMethodWorker.invokeTestMethods(TestMethodWorker.java:125)
	at org.testng.internal.TestMethodWorker.run(TestMethodWorker.java:108)
	at org.testng.TestRunner.privateRun(TestRunner.java:774)
	at org.testng.TestRunner.run(TestRunner.java:624)
	at org.testng.SuiteRunner.runTest(SuiteRunner.java:359)
	at org.testng.SuiteRunner.runSequentially(SuiteRunner.java:354)
	at org.testng.SuiteRunner.privateRun(SuiteRunner.java:312)
	at org.testng.SuiteRunner.run(SuiteRunner.java:261)
	at org.testng.SuiteRunnerWorker.runSuite(SuiteRunnerWorker.java:52)
	at org.testng.SuiteRunnerWorker.run(SuiteRunnerWorker.java:86)
	at org.testng.TestNG.runSuitesSequentially(TestNG.java:1215)
	at org.testng.TestNG.runSuitesLocally(TestNG.java:1140)
	at org.testng.TestNG.run(TestNG.java:1048)
	at org.testng.TestNG.privateMain(TestNG.java:1355)
	at org.testng.TestNG.main(TestNG.java:1324)
]]>
            </full-stacktrace>
          </exception> <!-- java.lang.IndexOutOfBoundsException -->
          <reporter-output>
          </reporter-output>
        </test-method> <!-- Recharge -->
        <test-method status="PASS" signature="Withdrawals()[pri:0, instance:com.my.test.TestCase@7c6908d7]" name="Withdrawals" duration-ms="33494" started-at="2016-10-18T15:05:36Z" finished-at="2016-10-18T15:06:09Z">
          <reporter-output>
          </reporter-output>
        </test-method> <!-- Withdrawals -->
        <test-method status="FAIL" signature="Ticket()[pri:0, instance:com.my.test.TestCase@7c6908d7]" name="Ticket" duration-ms="57932" started-at="2016-10-18T15:06:09Z" finished-at="2016-10-18T15:07:07Z">
          <exception class="java.lang.AssertionError">
            <message>
              <![CDATA[expected [恭喜您，支付成功] but found [恭喜您,支付成功]]]>
            </message>
            <full-stacktrace>
              <![CDATA[java.lang.AssertionError: expected [恭喜您，支付成功] but found [恭喜您,支付成功]
	at org.testng.Assert.fail(Assert.java:94)
	at org.testng.Assert.failNotEquals(Assert.java:496)
	at org.testng.Assert.assertEquals(Assert.java:125)
	at org.testng.Assert.assertEquals(Assert.java:178)
	at org.testng.Assert.assertEquals(Assert.java:188)
	at com.my.business.SimpleBusiness.BuyTicket(Unknown Source)
	at com.my.test.TestCase.Ticket(Unknown Source)
	at sun.reflect.NativeMethodAccessorImpl.invoke0(Native Method)
	at sun.reflect.NativeMethodAccessorImpl.invoke(NativeMethodAccessorImpl.java:62)
	at sun.reflect.DelegatingMethodAccessorImpl.invoke(DelegatingMethodAccessorImpl.java:43)
	at java.lang.reflect.Method.invoke(Method.java:498)
	at org.testng.internal.MethodInvocationHelper.invokeMethod(MethodInvocationHelper.java:85)
	at org.testng.internal.Invoker.invokeMethod(Invoker.java:639)
	at org.testng.internal.Invoker.invokeTestMethod(Invoker.java:816)
	at org.testng.internal.Invoker.invokeTestMethods(Invoker.java:1124)
	at org.testng.internal.TestMethodWorker.invokeTestMethods(TestMethodWorker.java:125)
	at org.testng.internal.TestMethodWorker.run(TestMethodWorker.java:108)
	at org.testng.TestRunner.privateRun(TestRunner.java:774)
	at org.testng.TestRunner.run(TestRunner.java:624)
	at org.testng.SuiteRunner.runTest(SuiteRunner.java:359)
	at org.testng.SuiteRunner.runSequentially(SuiteRunner.java:354)
	at org.testng.SuiteRunner.privateRun(SuiteRunner.java:312)
	at org.testng.SuiteRunner.run(SuiteRunner.java:261)
	at org.testng.SuiteRunnerWorker.runSuite(SuiteRunnerWorker.java:52)
	at org.testng.SuiteRunnerWorker.run(SuiteRunnerWorker.java:86)
	at org.testng.TestNG.runSuitesSequentially(TestNG.java:1215)
	at org.testng.TestNG.runSuitesLocally(TestNG.java:1140)
	at org.testng.TestNG.run(TestNG.java:1048)
	at org.testng.TestNG.privateMain(TestNG.java:1355)
	at org.testng.TestNG.main(TestNG.java:1324)
]]>
            </full-stacktrace>
          </exception> <!-- java.lang.AssertionError -->
          <reporter-output>
          </reporter-output>
        </test-method> <!-- Ticket -->
      </class> <!-- com.my.test.TestCase -->
    </test> <!-- Test -->
  </suite> <!-- Suite -->
</testng-results>
